Workbook

Sheet How to Use
A1: Digital Footprint Removal Tracker
A3: LEGEND
A4: Yellow cells with blue text = inputs you fill in (Client Profile, Summary follow-up days).
A5: Grey-blue cells on Findings = formulas (ID, Follow-up Due, Days Since Request). Do not type over them.
A6: White cells on Findings = one row per URL found. Dropdown columns pull options from the Lists sheet.
A7: Red Follow-up Due = request is overdue for a chase. Grey italic rows = namesakes (not your client).
A9: WORKFLOW
A10: 1. Get the signed authorization first and record it on Client Profile.
A11: 2. Fill in Client Profile identifiers; these drive the search queries.
A12: 3. Run the scanner (or search manually) and paste / import results into Findings, starting at row 2 (overwrite the example row).
A13: 4. Review every row: set Match Confidence by hand. Never file a removal request for an Unverified or Namesake row.
A14: 5. Set Severity and Removal Method, send requests, log the date and reference number.
... A24: Removal methods referencing KVKK, GDPR and Law 5651 are general categories, not legal advice. Have a lawyer review legal requests and court applications.

Sheet Client Profile
A1: Client Profile & Search Identifiers
A2: Everything the search script and you will look for. Fill in the yellow cells; separate multiple values with semicolons.
A4: CLIENT
A5: Client ID / Case # | B5: CASE-2026-001
A6: Full legal name | B6: Ahmet Yılmaz
A7: Name variants & spellings | B7: Ahmet Yilmaz; A. Yılmaz; Ahmet Kemal Yılmaz
A8: Date of birth (for match verification)
A9: Current & past cities | B9: İstanbul; Ankara
A10: Current & past addresses
A11: Phone numbers | B11: +90 5xx xxx xx xx
A12: Email addresses
A13: Usernames / handles
A14: Employers (current & past)
A15: Schools
A16: Known relatives' names (for broker matching)
A17: Photos provided for reverse image search? (path)
A18: ENGAGEMENT
A19: Signed authorization received? | B19: No
A20: Authorization date
A21: Scope agreed (what to remove / keep)
A22: Accounts client wants to KEEP
A23: Engagement start date
A24: Removal goal / end date
A25: Re-scan frequency | B25: Monthly
A26: Next re-scan date
A27: Data retention: delete client data on

Sheet Summary
B1: Footprint Removal Summary
B2: ='Client Profile'!B6&" | "&'Client Profile'!B5
B4: Follow-up days after request | C4: 30
B6: Overview | C6: Count | D6: % of relevant
B7: Total rows found | C7: =COUNTIF(Findings!$C$2:$C$1000,"?*")
B8: Relevant (Confirmed + Likely) | C8: =COUNTIF(Findings!$H$2:$H$1000,"Confirmed")+COUNTIF(Findings!$H$2:$H$1000,"Likely")
B9: Namesakes excluded | C9: =COUNTIF(Findings!$H$2:$H$1000,"Namesake (not client)")
B10: Unverified (needs review) | C10: =COUNTIF(Findings!$H$2:$H$1000,"Unverified")
B11: Removed or deindexed | C11: =SUMPRODUCT(((Findings!$H$2:$H$1000="Confirmed")+(Findings!$H$2:$H$1000="Likely"))*((Findings!$Y$2:$Y$1000="Removed")+(Findings!$Y$2:$Y$1000="Deindexed only"))) | D11: =IFERROR(C11/$C$8,0)
B12: Overdue follow-ups | C12: =SUMPRODUCT((Findings!$W$2:$W$1000<>"")*(Findings!$X$2:$X$1000<>"")*(Findings!$X$2:$X$1000>=$C$4))
B14: By Severity (relevant only) | C14: Count | D14: % of relevant
B15: Critical | C15: =SUMPRODUCT(((Findings!$H$2:$H$1000="Confirmed")+(Findings!$H$2:$H$1000="Likely"))*(Findings!$Q$2:$Q$1000=B15)) | D15: =IFERROR(C15/$C$8,0)
B16: High | C16: =SUMPRODUCT(((Findings!$H$2:$H$1000="Confirmed")+(Findings!$H$2:$H$1000="Likely"))*(Findings!$Q$2:$Q$1000=B16)) | D16: =IFERROR(C16/$C$8,0)
B17: Medium | C17: =SUMPRODUCT(((Findings!$H$2:$H$1000="Confirmed")+(Findings!$H$2:$H$1000="Likely"))*(Findings!$Q$2:$Q$1000=B17)) | D17: =IFERROR(C17/$C$8,0)
B18: Low | C18: =SUMPRODUCT(((Findings!$H$2:$H$1000="Confirmed")+(Findings!$H$2:$H$1000="Likely"))*(Findings!$Q$2:$Q$1000=B18)) | D18: =IFERROR(C18/$C$8,0)
B20: By Status (relevant only) | C20: Count | D20: % of relevant
B21: Not started | C21: =SUMPRODUCT(((Findings!$H$2:$H$1000="Confirmed")+(Findings!$H$2:$H$1000="Likely"))*(Findings!$Y$2:$Y$1000=B21)) | D21: =IFERROR(C21/$C$8,0)
B22: Awaiting client input | C22: =SUMPRODUCT(((Findings!$H$2:$H$1000="Confirmed")+(Findings!$H$2:$H$1000="Likely"))*(Findings!$Y$2:$Y$1000=B22)) | D22: =IFERROR(C22/$C$8,0)
B23: Requested | C23: =SUMPRODUCT(((Findings!$H$2:$H$1000="Confirmed")+(Findings!$H$2:$H$1000="Likely"))*(Findings!$Y$2:$Y$1000=B23)) | D23: =IFERROR(C23/$C$8,0)
B24: Pending / in review | C24: =SUMPRODUCT(((Findings!$H$2:$H$1000="Confirmed")+(Findings!$H$2:$H$1000="Likely"))*(Findings!$Y$2:$Y$1000=B24)) | D24: =IFERROR(C24/$C$8,0)
B25: Removed | C25: =SUMPRODUCT(((Findings!$H$2:$H$1000="Confirmed")+(Findings!$H$2:$H$1000="Likely"))*(Findings!$Y$2:$Y$1000=B25)) | D25: =IFERROR(C25/$C$8,0)
B26: Deindexed only | C26: =SUMPRODUCT(((Findings!$H$2:$H$1000="Confirmed")+(Findings!$H$2:$H$1000="Likely"))*(Findings!$Y$2:$Y$1000=B26)) | D26: =IFERROR(C26/$C$8,0)
B27: Refused | C27: =SUMPRODUCT(((Findings!$H$2:$H$1000="Confirmed")+(Findings!$H$2:$H$1000="Likely"))*(Findings!$Y$2:$Y$1000=B27)) | D27: =IFERROR(C27/$C$8,0)
B28: Re-appeared | C28: =SUMPRODUCT(((Findings!$H$2:$H$1000="Confirmed")+(Findings!$H$2:$H$1000="Likely"))*(Findings!$Y$2:$Y$1000=B28)) | D28: =IFERROR(C28/$C$8,0)
B29: No action needed | C29: =SUMPRODUCT(((Findings!$H$2:$H$1000="Confirmed")+(Findings!$H$2:$H$1000="Likely"))*(Findings!$Y$2:$Y$1000=B29)) | D29: =IFERROR(C29/$C$8,0)
B31: By Site Category (relevant only) | C31: Count | D31: % of relevant
B32: Data broker / people search | C32: =SUMPRODUCT(((Findings!$H$2:$H$1000="Confirmed")+(Findings!$H$2:$H$1000="Likely"))*(Findings!$F$2:$F$1000=B32)) | D32: =IFERROR(C32/$C$8,0)
B33: News / media | C33: =SUMPRODUCT(((Findings!$H$2:$H$1000="Confirmed")+(Findings!$H$2:$H$1000="Likely"))*(Findings!$F$2:$F$1000=B33)) | D33: =IFERROR(C33/$C$8,0)
B34: Social media | C34: =SUMPRODUCT(((Findings!$H$2:$H$1000="Confirmed")+(Findings!$H$2:$H$1000="Likely"))*(Findings!$F$2:$F$1000=B34)) | D34: =IFERROR(C34/$C$8,0)
B35: Forum / community | C35: =SUMPRODUCT(((Findings!$H$2:$H$1000="Confirmed")+(Findings!$H$2:$H$1000="Likely"))*(Findings!$F$2:$F$1000=B35)) | D35: =IFERROR(C35/$C$8,0)
B36: Blog | C36: =SUMPRODUCT(((Findings!$H$2:$H$1000="Confirmed")+(Findings!$H$2:$H$1000="Likely"))*(Findings!$F$2:$F$1000=B36)) | D36: =IFERROR(C36/$C$8,0)
B37: Business directory | C37: =SUMPRODUCT(((Findings!$H$2:$H$1000="Confirmed")+(Findings!$H$2:$H$1000="Likely"))*(Findings!$F$2:$F$1000=B37)) | D37: =IFERROR(C37/$C$8,0)
B38: Government / court record | C38: =SUMPRODUCT(((Findings!$H$2:$H$1000="Confirmed")+(Findings!$H$2:$H$1000="Likely"))*(Findings!$F$2:$F$1000=B38)) | D38: =IFERROR(C38/$C$8,0)
B39: Professional network | C39: =SUMPRODUCT(((Findings!$H$2:$H$1000="Confirmed")+(Findings!$H$2:$H$1000="Likely"))*(Findings!$F$2:$F$1000=B39)) | D39: =IFERROR(C39/$C$8,0)
B40: Image / video host | C40: =SUMPRODUCT(((Findings!$H$2:$H$1000="Confirmed")+(Findings!$H$2:$H$1000="Likely"))*(Findings!$F$2:$F$1000=B40)) | D40: =IFERROR(C40/$C$8,0)
B41: Archive / cache | C41: =SUMPRODUCT(((Findings!$H$2:$H$1000="Confirmed")+(Findings!$H$2:$H$1000="Likely"))*(Findings!$F$2:$F$1000=B41)) | D41: =IFERROR(C41/$C$8,0)
B42: Review site | C42: =SUMPRODUCT(((Findings!$H$2:$H$1000="Confirmed")+(Findings!$H$2:$H$1000="Likely"))*(Findings!$F$2:$F$1000=B42)) | D42: =IFERROR(C42/$C$8,0)
B43: Other | C43: =SUMPRODUCT(((Findings!$H$2:$H$1000="Confirmed")+(Findings!$H$2:$H$1000="Likely"))*(Findings!$F$2:$F$1000=B43)) | D43: =IFERROR(C43/$C$8,0)
B45: By Removal Method (relevant only) | C45: Count | D45: % of relevant
B46: Client deletes own account | C46: =SUMPRODUCT(((Findings!$H$2:$H$1000="Confirmed")+(Findings!$H$2:$H$1000="Likely"))*(Findings!$R$2:$R$1000=B46)) | D46: =IFERROR(C46/$C$8,0)
...

Sheet Findings
A1: ID | B1: Date Found | C1: Site Link | D1: Domain | E1: Site Owner | F1: Site Category | G1: Jurisdiction / Hosting Country | H1: Match Confidence | I1: Client's Own Account? | J1: Content Type | K1: Data Types Exposed | L1: Mentioned Places (on page) | M1: Mentions on Page | N1: Google Rank for Name | O1: Indexed in Google? | P1: Archived Copies? | Q1: Severity | R1: Removal Method | S1: Removal Contact / Form URL | T1: Deindex Fallback | U1: Request Sent Date | V1: Request Reference # | W1: Follow-up Due | X1: Days Since Request | Y1: Status | Z1: Last Checked | AA1: Evidence (screenshot path) | AB1: Notes
A2: =IF(C2="","",ROW()-1) | B2: 46293 | C2: https://www.example-people-directory.com/profile/ahmet-yilmaz-istanbul | D2: example-people-directory.com | E2: Example Directory Ltd. | F2: Data broker / people search | G2: USA | H2: Confirmed | I2: No | J2: Listing | K2: Full name, Phone, Past address, Relatives | L2: Title, profile body, relatives section | M2: 4 | N2: 3 | O2: Yes | P2: No | Q2: High | R2: Site opt-out form | S2: https://www.example-people-directory.com/optout | T2: Google personal info removal form | U2: 46294 | V2: OPT-448213 | W2: =IF(U2="","",U2+Summary!$C$4) | X2: =IF(OR(U2="",Y2="Removed",Y2="Deindexed only",Y2="No action needed"),"",TODAY()-U2) | Y2: Requested | Z2: 46294 | AA2: evidence/0001_example-people-directory.png | AB2: EXAMPLE ROW - delete or overwrite. Opt-out needs email confirmation from client.
A3: =IF(C3="","",ROW()-1) | W3: =IF(U3="","",U3+Summary!$C$4) | X3: =IF(OR(U3="",Y3="Removed",Y3="Deindexed only",Y3="No action needed"),"",TODAY()-U3)
A4: =IF(C4="","",ROW()-1) | W4: =IF(U4="","",U4+Summary!$C$4) | X4: =IF(OR(U4="",Y4="Removed",Y4="Deindexed only",Y4="No action needed"),"",TODAY()-U4)
A5: =IF(C5="","",ROW()-1) | W5: =IF(U5="","",U5+Summary!$C$4) | X5: =IF(OR(U5="",Y5="Removed",Y5="Deindexed only",Y5="No action needed"),"",TODAY()-U5)
A6: =IF(C6="","",ROW()-1) | W6: =IF(U6="","",U6+Summary!$C$4) | X6: =IF(OR(U6="",Y6="Removed",Y6="Deindexed only",Y6="No action needed"),"",TODAY()-U6)
A7: =IF(C7="","",ROW()-1) | W7: =IF(U7="","",U7+Summary!$C$4) | X7: =IF(OR(U7="",Y7="Removed",Y7="Deindexed only",Y7="No action needed"),"",TODAY()-U7)
A8: =IF(C8="","",ROW()-1) | W8: =IF(U8="","",U8+Summary!$C$4) | X8: =IF(OR(U8="",Y8="Removed",Y8="Deindexed only",Y8="No action needed"),"",TODAY()-U8)
A9: =IF(C9="","",ROW()-1) | W9: =IF(U9="","",U9+Summary!$C$4) | X9: =IF(OR(U9="",Y9="Removed",Y9="Deindexed only",Y9="No action needed"),"",TODAY()-U9)
A10: =IF(C10="","",ROW()-1) | W10: =IF(U10="","",U10+Summary!$C$4) | X10: =IF(OR(U10="",Y10="Removed",Y10="Deindexed only",Y10="No action needed"),"",TODAY()-U10)
A11: =IF(C11="","",ROW()-1) | W11: =IF(U11="","",U11+Summary!$C$4) | X11: =IF(OR(U11="",Y11="Removed",Y11="Deindexed only",Y11="No action needed"),"",TODAY()-U11)
A12: =IF(C12="","",ROW()-1) | W12: =IF(U12="","",U12+Summary!$C$4) | X12: =IF(OR(U12="",Y12="Removed",Y12="Deindexed only",Y12="No action needed"),"",TODAY()-U12)
A13: =IF(C13="","",ROW()-1) | W13: =IF(U13="","",U13+Summary!$C$4) | X13: =IF(OR(U13="",Y13="Removed",Y13="Deindexed only",Y13="No action needed"),"",TODAY()-U13)
A14: =IF(C14="","",ROW()-1) | W14: =IF(U14="","",U14+Summary!$C$4) | X14: =IF(OR(U14="",Y14="Removed",Y14="Deindexed only",Y14="No action needed"),"",TODAY()-U14)
... A1000: =IF(C1000="","",ROW()-1) | W1000: =IF(U1000="","",U1000+Summary!$C$4) | X1000: =IF(OR(U1000="",Y1000="Removed",Y1000="Deindexed only",Y1000="No action needed"),"",TODAY()-U1000)

Sheet Lists
A1: Site Category | B1: Match Confidence | C1: Yes/No | D1: Content Type | E1: Severity | F1: Removal Method | G1: Status
A2: Data broker / people search | B2: Confirmed | C2: Yes | D2: Text | E2: Critical | F2: Client deletes own account | G2: Not started
A3: News / media | B3: Likely | C3: No | D3: Image | E3: High | F3: Site opt-out form | G3: Awaiting client input
A4: Social media | B4: Unverified | C4: Unknown | D4: Video | E4: Medium | F4: Direct request to site owner | G4: Requested
A5: Forum / community | B5: Namesake (not client) | D5: PDF / document | E5: Low | F5: KVKK request (Law 6698) | G5: Pending / in review
A6: Blog | D6: Profile page | F6: GDPR Art. 17 erasure request | G6: Removed
A7: Business directory | D7: Listing | F7: Google 'Results about you' / personal info form | G7: Deindexed only
A8: Government / court record | D8: Comment | F8: Google Outdated Content tool | G8: Refused
A9: Professional network | D9: Cached copy | F9: Court application (Law 5651) | G9: Re-appeared
A10: Image / video host | F10: Lawyer / legal notice | G10: No action needed
A11: Archive / cache | F11: Hosting provider abuse report
A12: Review site | F12: No action (namesake / low value)
A13: Other | F13: Other
A15: Edit these lists to change dropdown options. Add new items directly below the last item in a column and extend the named range if needed.
